Workbook

Sheet Инструкция
A1: Цикл базы с поправкой на состояние
A2: Что делает таблица
A3: По опросу перед тренировкой считает снижение в процентных пунктах от ПМ, решает: по плану, снижение, Т на С с низкими процентами, лёгкий день или пропуск. Считает рабочий вес на сегодня и сдвигает дальнейший цикл: день с поправкой в следующем микроцикле повторяется без прибавки.
A4: Что заполнять (жёлтые ячейки)
A5: 1. Лист "Настройки": клиент, ПМ, шаг округления, скорость прогрессии, тип микроцикла. Правила поправки тоже там, их можно менять.
A6: 2. Лист "Дневник", перед тренировкой: дата, сон в часах, стресс, крепатура, энергия (1-5, где 5 отлично), инфекция с температурой да/нет, боль в груди или давление или острая боль да/нет.
A7: 3. После тренировки: фактический вес, повторы и запас повторов в главном рабочем подходе. Таблица посчитает расчётный ПМ и подскажет, когда его обновить.
A8: Опрос для клиента (отправить в бот перед тренировкой)
A9: Сколько часов спал? Стресс от 1 до 5 (5 = спокоен)? Крепатура в мышцах, которые сегодня работают, от 1 до 5 (5 = нет)? Энергия от 1 до 5 (5 = полно сил)? Есть инфекция с температурой? Есть боль в груди, скачет давление или острая боль в суставе?
A10: Правила
A11: Инфекция с температурой: тренировки нет (решение Микаела). Боль в груди, давление, острая боль: тренировки нет, решает Микаел. Снижение не больше максимума с листа "Настройки". База не меньше 4 рабочих подходов.
A12: Сигналы
... A16: Расчётный ПМ = вес х (1 + (повторы + запас) / 30), формула Эпли с запасом повторов. Считается, только если повторы + запас не больше 10.

Sheet Настройки
A1: Настройки цикла и правила поправки
A3: Клиент | B3: Пример: Иван
A4: База | B4: Жим лёжа
A5: ПМ, кг | B5: 165
A6: Шаг округления, кг | B6: 2.5
A7: Скорость прогрессии за микроцикл | B7: 0.04
A8: Микроцикл (М-С-Л-Т или С-Л-Т) | B8: С-Л-Т
A11: Проценты калькулятора
A12: День | B12: Базовый % | C12: Подводка (мк 4) | D12: Подходы мк1 | E12: мк2 | F12: мк3 | G12: мк4
A13: М | B13: 0.69 | C13: 0.69 | D13: 6 по 3 | E13: 6 по 3 | F13: 5 по 3 | G13: 4 по 3
A14: С | B14: 0.8 | C14: 0.8 | D14: 6 по 3 | E14: 5 по 3 | F14: 7 по 2 | G14: 4 по 2
A15: Л | B15: 0.57 | C15: 0.57 | D15: 4 по 5 | E15: 4 по 6 | F15: 4 по 6 | G15: 4 по 3
A16: Т | B16: 0.92 | C16: Проходка | D16: 4 по 2 | E16: 3 по 1 + 92%, 2 по 2 | F16: 3 по 1 + 92%, 2 по 2 | G16: Проходка 95-100%, 1 по 1 + 1 по 1
A17: Источник: база "Тренировочные планы", калькулятор Микаела. Рабочий % = базовый + скорость х (микроцикл - 1).
A19: Поправка по сну (часы)
A20: От, часов | B20: Уровень | C20: М, п.п. | D20: С, п.п. | E20: Л, п.п. | F20: Т, п.п. | G20: Замена дня
A21: 0 | B21: Не спал | C21: 0.1 | D21: 0.1 | E21: 0.05 | F21: 0.1 | G21: Только Л
A22: 3.5 | B22: Почти не спал | C22: 0.07 | D22: 0.07 | E22: 0.05 | F22: 0.07 | G22: Т на С
A23: 5 | B23: Недосып | C23: 0.03 | D23: 0.03 | E23: 0 | F23: 0.03 | G23: Нет
A24: 7 | B24: Норма | C24: 0 | D24: 0 | E24: 0 | F24: 0 | G24: Нет
A25: Пороги сна от Микаела: меньше 7 ч недосып, меньше 5 ч почти не спал, меньше 3-4 ч не спал. Пункты снижения: решение агента по жиму.
A27: Поправка по оценкам 1-5 (стресс, крепатура, энергия)
A28: Оценка | B28: Снижение, п.п.
A29: 1 | B29: 0.05
A30: 2 | B30: 0.03
A31: 3 | B31: 0.02
A32: 4 | B32: 0
A33: 5 | B33: 0
A34: 5 значит отлично (нет стресса, нет крепатуры, полно энергии), 1 значит очень плохо.
A36: Пороги решений
A37: Максимум суммарного снижения | B37: 0.1
A38: Т заменяю на С, если снижение от | B38: 0.05
A39: Любой день делаю Л, если снижение от | B39: 0.08
A40: "С с низкими процентами": минус пунктов от С | B40: 0.05
A41: Порог отклонения расчётного ПМ | B41: 0.03

Sheet Дневник
A1: Дневник цикла: жёлтое заполняет тренер или клиент, остальное считается само
A3: Дата | B3: Микро-цикл | C3: День по плану | D3: Сон, часов | E3: Стресс 1-5 | F3: Крепатура 1-5 | G3: Энергия 1-5 | H3: Инфекция с температурой (да/нет) | I3: Боль в груди, давление, острая боль (да/нет) | J3: Уровень сна | K3: Снижение по сну | L3: Снижение по опросу | M3: Итог снижения | N3: Решение | O3: День факт | P3: Поправка была | Q3: Сдвиг прогрессии | R3: Микроцикл для % | S3: План % | T3: Рабочий % | U3: Рабочий вес, кг | V3: Подходы по повторы | W3: Факт: вес | X3: Факт: повторы | Y3: Факт: запас повторов | Z3: Расчётный ПМ | AA3: Отклонение от ПМ | AB3: Последнее отклонение | AC3: Сигнал
B4: =IF(0<6*IF(Настройки!$B$8="С-Л-Т",3,4),INT(0/IF(Настройки!$B$8="С-Л-Т",3,4))+1,"") -> 1 | C4: =IF(B4="","",IF(Настройки!$B$8="С-Л-Т",CHOOSE(MOD(0,3)+1,"С","Л","Т"),CHOOSE(MOD(0,4)+1,"М","С","Л","Т"))) -> С | D4: 6 | E4: 3 | F4: 4 | G4: 4 | H4: нет | I4: нет | J4: =IF(D4="","",LOOKUP(D4,Настройки!$A$21:$A$24,Настройки!$B$21:$B$24)) -> Недосып | K4: =IF(OR(D4="",C4=""),0,LOOKUP(D4,Настройки!$A$21:$A$24,INDEX(Настройки!$C$21:$F$24,0,MATCH(C4,Настройки!$A$13:$A$16,0)))) -> 0.03 | L4: =IF(E4="",0,LOOKUP(E4,Настройки!$A$29:$A$33,Настройки!$B$29:$B$33))+IF(F4="",0,LOOKUP(F4,Настройки!$A$29:$A$33,Настройки!$B$29:$B$33))+IF(G4="",0,LOOKUP(G4,Настройки!$A$29:$A$33,Настройки!$B$29:$B$33)) -> 0.02 | M4: =MIN(Настройки!$B$37,K4+L4) -> 0.05 | N4: =IF(C4="","",IF(H4="да","Пропуск: инфекция",IF(I4="да","К тренеру, не тренироваться",IF(OR(IF(D4="","Нет",LOOKUP(D4,Настройки!$A$21:$A$24,Настройки!$G$21:$G$24))="Только Л",M4>=Настройки!$B$39),"Лёгкий день",IF(AND(C4="Т",OR(IF(D4="","Нет",LOOKUP(D4,Настройки!$A$21:$A$24,Настройки!$G$21:$G$24))="Т на С",M4>=Настройки!$B$38)),"Т на С с низкими %",IF(M4>0,"Снижение","По плану")))))) -> Снижение | O4: =IF(C4="","",IF(LEFT(N4,6)="Пропус","",IF(N4="К тренеру, не тренироваться","",IF(N4="Лёгкий день","Л",IF(N4="Т на С с низкими %","С",C4))))) -> С | P4: =IF(OR(N4="",N4="По плану"),0,1) -> 1 | Q4: 0 | R4: =IF(B4="","",MAX(1,B4-Q4)) -> 1 | S4: =IF(C4="","",IF(R4<=3,INDEX(Настройки!$B$13:$B$16,MATCH(C4,Настройки!$A$13:$A$16,0))+Настройки!$B$7*(R4-1),IF(R4=4,INDEX(Настройки!$C$13:$C$16,MATCH(C4,Настройки!$A$13:$A$16,0)),"Новый цикл"))) -> 0.8 | T4: =IF(OR(O4="",NOT(ISNUMBER(S4))),"",IF(N4="Т на С с низкими %",(INDEX(Настройки!$B$13:$B$16,2)+Настройки!$B$7*(MIN(R4,3)-1))-Настройки!$B$40,IF(N4="Лёгкий день",MIN(S4,(INDEX(Настройки!$B$13:$B$16,3)+Настройки!$B$7*(MIN(R4,3)-1)))-IF(C4="Л",M4,0),S4-M4))) -> 0.75 | U4: =IF(ISNUMBER(T4),ROUND(Настройки!$B$5*T4/Настройки!$B$6,0)*Настройки!$B$6,"") -> 125 | V4: =IF(O4="","",IF(NOT(ISNUMBER(S4)),S4,IF(O4="Л",INDEX(Настройки!$D$13:$G$16,3,MIN(R4,4)),INDEX(Настройки!$D$13:$G$16,MATCH(O4,Настройки!$A$13:$A$16,0),MIN(R4,4)))&IF(M4>0," (подходов не меньше 4)",""))) -> 6 по 3 (подходов не меньше 4) | Z4: =IF(AND(N(W4)>0,N(X4)>0,N(X4)+N(Y4)<=10),W4*(1+(X4+N(Y4))/30),"") | AA4: =IF(Z4="","",Z4/Настройки!$B$5-1) | AB4: =IF(AA4="","",AA4) | AC4: =IF(C4="","",TRIM(IF(AND(P4=1,COUNTIFS($B$4:$B$27,B4-1,$P$4:$P$27,1)>0),"Две поправки подряд: проверить ПМ или разгрузка. ","")&IF(AA4="","",IF(AND(AA4>Настройки!$B$41,N("")>Настройки!$B$41),"ПМ выше расчёта 2 раза: обновить ПМ. ",IF(AND(AA4<-Настройки!$B$41,N("")<-Настройки!$B$41),"ПМ ниже расчёта 2 раза: проверить ПМ. ","")))))
B5: =IF(1<6*IF(Настройки!$B$8="С-Л-Т",3,4),INT(1/IF(Настройки!$B$8="С-Л-Т",3,4))+1,"") -> 1 | C5: =IF(B5="","",IF(Настройки!$B$8="С-Л-Т",CHOOSE(MOD(1,3)+1,"С","Л","Т"),CHOOSE(MOD(1,4)+1,"М","С","Л","Т"))) -> Л | D5: 7.5 | E5: 5 | F5: 5 | G5: 5 | H5: нет | I5: нет | J5: =IF(D5="","",LOOKUP(D5,Настройки!$A$21:$A$24,Настройки!$B$21:$B$24)) -> Норма | K5: =IF(OR(D5="",C5=""),0,LOOKUP(D5,Настройки!$A$21:$A$24,INDEX(Настройки!$C$21:$F$24,0,MATCH(C5,Настройки!$A$13:$A$16,0)))) -> 0 | L5: =IF(E5="",0,LOOKUP(E5,Настройки!$A$29:$A$33,Настройки!$B$29:$B$33))+IF(F5="",0,LOOKUP(F5,Настройки!$A$29:$A$33,Настройки!$B$29:$B$33))+IF(G5="",0,LOOKUP(G5,Настройки!$A$29:$A$33,Настройки!$B$29:$B$33)) -> 0 | M5: =MIN(Настройки!$B$37,K5+L5) -> 0 | N5: =IF(C5="","",IF(H5="да","Пропуск: инфекция",IF(I5="да","К тренеру, не тренироваться",IF(OR(IF(D5="","Нет",LOOKUP(D5,Настройки!$A$21:$A$24,Настройки!$G$21:$G$24))="Только Л",M5>=Настройки!$B$39),"Лёгкий день",IF(AND(C5="Т",OR(IF(D5="","Нет",LOOKUP(D5,Настройки!$A$21:$A$24,Настройки!$G$21:$G$24))="Т на С",M5>=Настройки!$B$38)),"Т на С с низкими %",IF(M5>0,"Снижение","По плану")))))) -> По плану | O5: =IF(C5="","",IF(LEFT(N5,6)="Пропус","",IF(N5="К тренеру, не тренироваться","",IF(N5="Лёгкий день","Л",IF(N5="Т на С с низкими %","С",C5))))) -> Л | P5: =IF(OR(N5="",N5="По плану"),0,1) -> 0 | Q5: =COUNTIFS($C$4:C4,C5,$P$4:P4,1) -> 0 | R5: =IF(B5="","",MAX(1,B5-Q5)) -> 1 | S5: =IF(C5="","",IF(R5<=3,INDEX(Настройки!$B$13:$B$16,MATCH(C5,Настройки!$A$13:$A$16,0))+Настройки!$B$7*(R5-1),IF(R5=4,INDEX(Настройки!$C$13:$C$16,MATCH(C5,Настройки!$A$13:$A$16,0)),"Новый цикл"))) -> 0.57 | T5: =IF(OR(O5="",NOT(ISNUMBER(S5))),"",IF(N5="Т на С с низкими %",(INDEX(Настройки!$B$13:$B$16,2)+Настройки!$B$7*(MIN(R5,3)-1))-Настройки!$B$40,IF(N5="Лёгкий день",MIN(S5,(INDEX(Настройки!$B$13:$B$16,3)+Настройки!$B$7*(MIN(R5,3)-1)))-IF(C5="Л",M5,0),S5-M5))) -> 0.57 | U5: =IF(ISNUMBER(T5),ROUND(Настройки!$B$5*T5/Настройки!$B$6,0)*Настройки!$B$6,"") -> 95 | V5: =IF(O5="","",IF(NOT(ISNUMBER(S5)),S5,IF(O5="Л",INDEX(Настройки!$D$13:$G$16,3,MIN(R5,4)),INDEX(Настройки!$D$13:$G$16,MATCH(O5,Настройки!$A$13:$A$16,0),MIN(R5,4)))&IF(M5>0," (подходов не меньше 4)",""))) -> 4 по 5 | Z5: =IF(AND(N(W5)>0,N(X5)>0,N(X5)+N(Y5)<=10),W5*(1+(X5+N(Y5))/30),"") | AA5: =IF(Z5="","",Z5/Настройки!$B$5-1) | AB5: =IF(AA5="",AB4,AA5) | AC5: =IF(C5="","",TRIM(IF(AND(P5=1,COUNTIFS($B$4:$B$27,B5-1,$P$4:$P$27,1)>0),"Две поправки подряд: проверить ПМ или разгрузка. ","")&IF(AA5="","",IF(AND(AA5>Настройки!$B$41,N(AB4)>Настройки!$B$41),"ПМ выше расчёта 2 раза: обновить ПМ. ",IF(AND(AA5<-Настройки!$B$41,N(AB4)<-Настройки!$B$41),"ПМ ниже расчёта 2 раза: проверить ПМ. ","")))))
B6: =IF(2<6*IF(Настройки!$B$8="С-Л-Т",3,4),INT(2/IF(Настройки!$B$8="С-Л-Т",3,4))+1,"") -> 1 | C6: =IF(B6="","",IF(Настройки!$B$8="С-Л-Т",CHOOSE(MOD(2,3)+1,"С","Л","Т"),CHOOSE(MOD(2,4)+1,"М","С","Л","Т"))) -> Т | J6: =IF(D6="","",LOOKUP(D6,Настройки!$A$21:$A$24,Настройки!$B$21:$B$24)) | K6: =IF(OR(D6="",C6=""),0,LOOKUP(D6,Настройки!$A$21:$A$24,INDEX(Настройки!$C$21:$F$24,0,MATCH(C6,Настройки!$A$13:$A$16,0)))) -> 0 | L6: =IF(E6="",0,LOOKUP(E6,Настройки!$A$29:$A$33,Настройки!$B$29:$B$33))+IF(F6="",0,LOOKUP(F6,Настройки!$A$29:$A$33,Настройки!$B$29:$B$33))+IF(G6="",0,LOOKUP(G6,Настройки!$A$29:$A$33,Настройки!$B$29:$B$33)) -> 0 | M6: =MIN(Настройки!$B$37,K6+L6) -> 0 | N6: =IF(C6="","",IF(H6="да","Пропуск: инфекция",IF(I6="да","К тренеру, не тренироваться",IF(OR(IF(D6="","Нет",LOOKUP(D6,Настройки!$A$21:$A$24,Настройки!$G$21:$G$24))="Только Л",M6>=Настройки!$B$39),"Лёгкий день",IF(AND(C6="Т",OR(IF(D6="","Нет",LOOKUP(D6,Настройки!$A$21:$A$24,Настройки!$G$21:$G$24))="Т на С",M6>=Настройки!$B$38)),"Т на С с низкими %",IF(M6>0,"Снижение","По плану")))))) -> По плану | O6: =IF(C6="","",IF(LEFT(N6,6)="Пропус","",IF(N6="К тренеру, не тренироваться","",IF(N6="Лёгкий день","Л",IF(N6="Т на С с низкими %","С",C6))))) -> Т | P6: =IF(OR(N6="",N6="По плану"),0,1) -> 0 | Q6: =COUNTIFS($C$4:C5,C6,$P$4:P5,1) -> 0 | R6: =IF(B6="","",MAX(1,B6-Q6)) -> 1 | S6: =IF(C6="","",IF(R6<=3,INDEX(Настройки!$B$13:$B$16,MATCH(C6,Настройки!$A$13:$A$16,0))+Настройки!$B$7*(R6-1),IF(R6=4,INDEX(Настройки!$C$13:$C$16,MATCH(C6,Настройки!$A$13:$A$16,0)),"Новый цикл"))) -> 0.92 | T6: =IF(OR(O6="",NOT(ISNUMBER(S6))),"",IF(N6="Т на С с низкими %",(INDEX(Настройки!$B$13:$B$16,2)+Настройки!$B$7*(MIN(R6,3)-1))-Настройки!$B$40,IF(N6="Лёгкий день",MIN(S6,(INDEX(Настройки!$B$13:$B$16,3)+Настройки!$B$7*(MIN(R6,3)-1)))-IF(C6="Л",M6,0),S6-M6))) -> 0.92 | U6: =IF(ISNUMBER(T6),ROUND(Настройки!$B$5*T6/Настройки!$B$6,0)*Настройки!$B$6,"") -> 152.5 | V6: =IF(O6="","",IF(NOT(ISNUMBER(S6)),S6,IF(O6="Л",INDEX(Настройки!$D$13:$G$16,3,MIN(R6,4)),INDEX(Настройки!$D$13:$G$16,MATCH(O6,Настройки!$A$13:$A$16,0),MIN(R6,4)))&IF(M6>0," (подходов не меньше 4)",""))) -> 4 по 2 | Z6: =IF(AND(N(W6)>0,N(X6)>0,N(X6)+N(Y6)<=10),W6*(1+(X6+N(Y6))/30),"") | AA6: =IF(Z6="","",Z6/Настройки!$B$5-1) | AB6: =IF(AA6="",AB5,AA6) | AC6: =IF(C6="","",TRIM(IF(AND(P6=1,COUNTIFS($B$4:$B$27,B6-1,$P$4:$P$27,1)>0),"Две поправки подряд: проверить ПМ или разгрузка. ","")&IF(AA6="","",IF(AND(AA6>Настройки!$B$41,N(AB5)>Настройки!$B$41),"ПМ выше расчёта 2 раза: обновить ПМ. ",IF(AND(AA6<-Настройки!$B$41,N(AB5)<-Настройки!$B$41),"ПМ ниже расчёта 2 раза: проверить ПМ. ","")))))
B7: =IF(3<6*IF(Настройки!$B$8="С-Л-Т",3,4),INT(3/IF(Настройки!$B$8="С-Л-Т",3,4))+1,"") -> 2 | C7: =IF(B7="","",IF(Настройки!$B$8="С-Л-Т",CHOOSE(MOD(3,3)+1,"С","Л","Т"),CHOOSE(MOD(3,4)+1,"М","С","Л","Т"))) -> С | J7: =IF(D7="","",LOOKUP(D7,Настройки!$A$21:$A$24,Настройки!$B$21:$B$24)) | K7: =IF(OR(D7="",C7=""),0,LOOKUP(D7,Настройки!$A$21:$A$24,INDEX(Настройки!$C$21:$F$24,0,MATCH(C7,Настройки!$A$13:$A$16,0)))) -> 0 | L7: =IF(E7="",0,LOOKUP(E7,Настройки!$A$29:$A$33,Настройки!$B$29:$B$33))+IF(F7="",0,LOOKUP(F7,Настройки!$A$29:$A$33,Настройки!$B$29:$B$33))+IF(G7="",0,LOOKUP(G7,Настройки!$A$29:$A$33,Настройки!$B$29:$B$33)) -> 0 | M7: =MIN(Настройки!$B$37,K7+L7) -> 0 | N7: =IF(C7="","",IF(H7="да","Пропуск: инфекция",IF(I7="да","К тренеру, не тренироваться",IF(OR(IF(D7="","Нет",LOOKUP(D7,Настройки!$A$21:$A$24,Настройки!$G$21:$G$24))="Только Л",M7>=Настройки!$B$39),"Лёгкий день",IF(AND(C7="Т",OR(IF(D7="","Нет",LOOKUP(D7,Настройки!$A$21:$A$24,Настройки!$G$21:$G$24))="Т на С",M7>=Настройки!$B$38)),"Т на С с низкими %",IF(M7>0,"Снижение","По плану")))))) -> По плану | O7: =IF(C7="","",IF(LEFT(N7,6)="Пропус","",IF(N7="К тренеру, не тренироваться","",IF(N7="Лёгкий день","Л",IF(N7="Т на С с низкими %","С",C7))))) -> С | P7: =IF(OR(N7="",N7="По плану"),0,1) -> 0 | Q7: =COUNTIFS($C$4:C6,C7,$P$4:P6,1) -> 1 | R7: =IF(B7="","",MAX(1,B7-Q7)) -> 1 | S7: =IF(C7="","",IF(R7<=3,INDEX(Настройки!$B$13:$B$16,MATCH(C7,Настройки!$A$13:$A$16,0))+Настройки!$B$7*(R7-1),IF(R7=4,INDEX(Настройки!$C$13:$C$16,MATCH(C7,Настройки!$A$13:$A$16,0)),"Новый цикл"))) -> 0.8 | T7: =IF(OR(O7="",NOT(ISNUMBER(S7))),"",IF(N7="Т на С с низкими %",(INDEX(Настройки!$B$13:$B$16,2)+Настройки!$B$7*(MIN(R7,3)-1))-Настройки!$B$40,IF(N7="Лёгкий день",MIN(S7,(INDEX(Настройки!$B$13:$B$16,3)+Настройки!$B$7*(MIN(R7,3)-1)))-IF(C7="Л",M7,0),S7-M7))) -> 0.8 | U7: =IF(ISNUMBER(T7),ROUND(Настройки!$B$5*T7/Настройки!$B$6,0)*Настройки!$B$6,"") -> 132.5 | V7: =IF(O7="","",IF(NOT(ISNUMBER(S7)),S7,IF(O7="Л",INDEX(Настройки!$D$13:$G$16,3,MIN(R7,4)),INDEX(Настройки!$D$13:$G$16,MATCH(O7,Настройки!$A$13:$A$16,0),MIN(R7,4)))&IF(M7>0," (подходов не меньше 4)",""))) -> 6 по 3 | Z7: =IF(AND(N(W7)>0,N(X7)>0,N(X7)+N(Y7)<=10),W7*(1+(X7+N(Y7))/30),"") | AA7: =IF(Z7="","",Z7/Настройки!$B$5-1) | AB7: =IF(AA7="",AB6,AA7) | AC7: =IF(C7="","",TRIM(IF(AND(P7=1,COUNTIFS($B$4:$B$27,B7-1,$P$4:$P$27,1)>0),"Две поправки подряд: проверить ПМ или разгрузка. ","")&IF(AA7="","",IF(AND(AA7>Настройки!$B$41,N(AB6)>Настройки!$B$41),"ПМ выше расчёта 2 раза: обновить ПМ. ",IF(AND(AA7<-Настройки!$B$41,N(AB6)<-Настройки!$B$41),"ПМ ниже расчёта 2 раза: проверить ПМ. ","")))))
B8: =IF(4<6*IF(Настройки!$B$8="С-Л-Т",3,4),INT(4/IF(Настройки!$B$8="С-Л-Т",3,4))+1,"") -> 2 | C8: =IF(B8="","",IF(Настройки!$B$8="С-Л-Т",CHOOSE(MOD(4,3)+1,"С","Л","Т"),CHOOSE(MOD(4,4)+1,"М","С","Л","Т"))) -> Л | J8: =IF(D8="","",LOOKUP(D8,Настройки!$A$21:$A$24,Настройки!$B$21:$B$24)) | K8: =IF(OR(D8="",C8=""),0,LOOKUP(D8,Настройки!$A$21:$A$24,INDEX(Настройки!$C$21:$F$24,0,MATCH(C8,Настройки!$A$13:$A$16,0)))) -> 0 | L8: =IF(E8="",0,LOOKUP(E8,Настройки!$A$29:$A$33,Настройки!$B$29:$B$33))+IF(F8="",0,LOOKUP(F8,Настройки!$A$29:$A$33,Настройки!$B$29:$B$33))+IF(G8="",0,LOOKUP(G8,Настройки!$A$29:$A$33,Настройки!$B$29:$B$33)) -> 0 | M8: =MIN(Настройки!$B$37,K8+L8) -> 0 | N8: =IF(C8="","",IF(H8="да","Пропуск: инфекция",IF(I8="да","К тренеру, не тренироваться",IF(OR(IF(D8="","Нет",LOOKUP(D8,Настройки!$A$21:$A$24,Настройки!$G$21:$G$24))="Только Л",M8>=Настройки!$B$39),"Лёгкий день",IF(AND(C8="Т",OR(IF(D8="","Нет",LOOKUP(D8,Настройки!$A$21:$A$24,Настройки!$G$21:$G$24))="Т на С",M8>=Настройки!$B$38)),"Т на С с низкими %",IF(M8>0,"Снижение","По плану")))))) -> По плану | O8: =IF(C8="","",IF(LEFT(N8,6)="Пропус","",IF(N8="К тренеру, не тренироваться","",IF(N8="Лёгкий день","Л",IF(N8="Т на С с низкими %","С",C8))))) -> Л | P8: =IF(OR(N8="",N8="По плану"),0,1) -> 0 | Q8: =COUNTIFS($C$4:C7,C8,$P$4:P7,1) -> 0 | R8: =IF(B8="","",MAX(1,B8-Q8)) -> 2 | S8: =IF(C8="","",IF(R8<=3,INDEX(Настройки!$B$13:$B$16,MATCH(C8,Настройки!$A$13:$A$16,0))+Настройки!$B$7*(R8-1),IF(R8=4,INDEX(Настройки!$C$13:$C$16,MATCH(C8,Настройки!$A$13:$A$16,0)),"Новый цикл"))) -> 0.61 | T8: =IF(OR(O8="",NOT(ISNUMBER(S8))),"",IF(N8="Т на С с низкими %",(INDEX(Настройки!$B$13:$B$16,2)+Настройки!$B$7*(MIN(R8,3)-1))-Настройки!$B$40,IF(N8="Лёгкий день",MIN(S8,(INDEX(Настройки!$B$13:$B$16,3)+Настройки!$B$7*(MIN(R8,3)-1)))-IF(C8="Л",M8,0),S8-M8))) -> 0.61 | U8: =IF(ISNUMBER(T8),ROUND(Настройки!$B$5*T8/Настройки!$B$6,0)*Настройки!$B$6,"") -> 100 | V8: =IF(O8="","",IF(NOT(ISNUMBER(S8)),S8,IF(O8="Л",INDEX(Настройки!$D$13:$G$16,3,MIN(R8,4)),INDEX(Настройки!$D$13:$G$16,MATCH(O8,Настройки!$A$13:$A$16,0),MIN(R8,4)))&IF(M8>0," (подходов не меньше 4)",""))) -> 4 по 6 | Z8: =IF(AND(N(W8)>0,N(X8)>0,N(X8)+N(Y8)<=10),W8*(1+(X8+N(Y8))/30),"") | AA8: =IF(Z8="","",Z8/Настройки!$B$5-1) | AB8: =IF(AA8="",AB7,AA8) | AC8: =IF(C8="","",TRIM(IF(AND(P8=1,COUNTIFS($B$4:$B$27,B8-1,$P$4:$P$27,1)>0),"Две поправки подряд: проверить ПМ или разгрузка. ","")&IF(AA8="","",IF(AND(AA8>Настройки!$B$41,N(AB7)>Настройки!$B$41),"ПМ выше расчёта 2 раза: обновить ПМ. ",IF(AND(AA8<-Настройки!$B$41,N(AB7)<-Настройки!$B$41),"ПМ ниже расчёта 2 раза: проверить ПМ. ","")))))
B9: =IF(5<6*IF(Настройки!$B$8="С-Л-Т",3,4),INT(5/IF(Настройки!$B$8="С-Л-Т",3,4))+1,"") -> 2 | C9: =IF(B9="","",IF(Настройки!$B$8="С-Л-Т",CHOOSE(MOD(5,3)+1,"С","Л","Т"),CHOOSE(MOD(5,4)+1,"М","С","Л","Т"))) -> Т | J9: =IF(D9="","",LOOKUP(D9,Настройки!$A$21:$A$24,Настройки!$B$21:$B$24)) | K9: =IF(OR(D9="",C9=""),0,LOOKUP(D9,Настройки!$A$21:$A$24,INDEX(Настройки!$C$21:$F$24,0,MATCH(C9,Настройки!$A$13:$A$16,0)))) -> 0 | L9: =IF(E9="",0,LOOKUP(E9,Настройки!$A$29:$A$33,Настройки!$B$29:$B$33))+IF(F9="",0,LOOKUP(F9,Настройки!$A$29:$A$33,Настройки!$B$29:$B$33))+IF(G9="",0,LOOKUP(G9,Настройки!$A$29:$A$33,Настройки!$B$29:$B$33)) -> 0 | M9: =MIN(Настройки!$B$37,K9+L9) -> 0 | N9: =IF(C9="","",IF(H9="да","Пропуск: инфекция",IF(I9="да","К тренеру, не тренироваться",IF(OR(IF(D9="","Нет",LOOKUP(D9,Настройки!$A$21:$A$24,Настройки!$G$21:$G$24))="Только Л",M9>=Настройки!$B$39),"Лёгкий день",IF(AND(C9="Т",OR(IF(D9="","Нет",LOOKUP(D9,Настройки!$A$21:$A$24,Настройки!$G$21:$G$24))="Т на С",M9>=Настройки!$B$38)),"Т на С с низкими %",IF(M9>0,"Снижение","По плану")))))) -> По плану | O9: =IF(C9="","",IF(LEFT(N9,6)="Пропус","",IF(N9="К тренеру, не тренироваться","",IF(N9="Лёгкий день","Л",IF(N9="Т на С с низкими %","С",C9))))) -> Т | P9: =IF(OR(N9="",N9="По плану"),0,1) -> 0 | Q9: =COUNTIFS($C$4:C8,C9,$P$4:P8,1) -> 0 | R9: =IF(B9="","",MAX(1,B9-Q9)) -> 2 | S9: =IF(C9="","",IF(R9<=3,INDEX(Настройки!$B$13:$B$16,MATCH(C9,Настройки!$A$13:$A$16,0))+Настройки!$B$7*(R9-1),IF(R9=4,INDEX(Настройки!$C$13:$C$16,MATCH(C9,Настройки!$A$13:$A$16,0)),"Новый цикл"))) -> 0.96 | T9: =IF(OR(O9="",NOT(ISNUMBER(S9))),"",IF(N9="Т на С с низкими %",(INDEX(Настройки!$B$13:$B$16,2)+Настройки!$B$7*(MIN(R9,3)-1))-Настройки!$B$40,IF(N9="Лёгкий день",MIN(S9,(INDEX(Настройки!$B$13:$B$16,3)+Настройки!$B$7*(MIN(R9,3)-1)))-IF(C9="Л",M9,0),S9-M9))) -> 0.96 | U9: =IF(ISNUMBER(T9),ROUND(Настройки!$B$5*T9/Настройки!$B$6,0)*Настройки!$B$6,"") -> 157.5 | V9: =IF(O9="","",IF(NOT(ISNUMBER(S9)),S9,IF(O9="Л",INDEX(Настройки!$D$13:$G$16,3,MIN(R9,4)),INDEX(Настройки!$D$13:$G$16,MATCH(O9,Настройки!$A$13:$A$16,0),MIN(R9,4)))&IF(M9>0," (подходов не меньше 4)",""))) -> 3 по 1 + 92%, 2 по 2 | Z9: =IF(AND(N(W9)>0,N(X9)>0,N(X9)+N(Y9)<=10),W9*(1+(X9+N(Y9))/30),"") | AA9: =IF(Z9="","",Z9/Настройки!$B$5-1) | AB9: =IF(AA9="",AB8,AA9) | AC9: =IF(C9="","",TRIM(IF(AND(P9=1,COUNTIFS($B$4:$B$27,B9-1,$P$4:$P$27,1)>0),"Две поправки подряд: проверить ПМ или разгрузка. ","")&IF(AA9="","",IF(AND(AA9>Настройки!$B$41,N(AB8)>Настройки!$B$41),"ПМ выше расчёта 2 раза: обновить ПМ. ",IF(AND(AA9<-Настройки!$B$41,N(AB8)<-Настройки!$B$41),"ПМ ниже расчёта 2 раза: проверить ПМ. ","")))))
B10: =IF(6<6*IF(Настройки!$B$8="С-Л-Т",3,4),INT(6/IF(Настройки!$B$8="С-Л-Т",3,4))+1,"") -> 3 | C10: =IF(B10="","",IF(Настройки!$B$8="С-Л-Т",CHOOSE(MOD(6,3)+1,"С","Л","Т"),CHOOSE(MOD(6,4)+1,"М","С","Л","Т"))) -> С | J10: =IF(D10="","",LOOKUP(D10,Настройки!$A$21:$A$24,Настройки!$B$21:$B$24)) | K10: =IF(OR(D10="",C10=""),0,LOOKUP(D10,Настройки!$A$21:$A$24,INDEX(Настройки!$C$21:$F$24,0,MATCH(C10,Настройки!$A$13:$A$16,0)))) -> 0 | L10: =IF(E10="",0,LOOKUP(E10,Настройки!$A$29:$A$33,Настройки!$B$29:$B$33))+IF(F10="",0,LOOKUP(F10,Настройки!$A$29:$A$33,Настройки!$B$29:$B$33))+IF(G10="",0,LOOKUP(G10,Настройки!$A$29:$A$33,Настройки!$B$29:$B$33)) -> 0 | M10: =MIN(Настройки!$B$37,K10+L10) -> 0 | N10: =IF(C10="","",IF(H10="да","Пропуск: инфекция",IF(I10="да","К тренеру, не тренироваться",IF(OR(IF(D10="","Нет",LOOKUP(D10,Настройки!$A$21:$A$24,Настройки!$G$21:$G$24))="Только Л",M10>=Настройки!$B$39),"Лёгкий день",IF(AND(C10="Т",OR(IF(D10="","Нет",LOOKUP(D10,Настройки!$A$21:$A$24,Настройки!$G$21:$G$24))="Т на С",M10>=Настройки!$B$38)),"Т на С с низкими %",IF(M10>0,"Снижение","По плану")))))) -> По плану | O10: =IF(C10="","",IF(LEFT(N10,6)="Пропус","",IF(N10="К тренеру, не тренироваться","",IF(N10="Лёгкий день","Л",IF(N10="Т на С с низкими %","С",C10))))) -> С | P10: =IF(OR(N10="",N10="По плану"),0,1) -> 0 | Q10: =COUNTIFS($C$4:C9,C10,$P$4:P9,1) -> 1 | R10: =IF(B10="","",MAX(1,B10-Q10)) -> 2 | S10: =IF(C10="","",IF(R10<=3,INDEX(Настройки!$B$13:$B$16,MATCH(C10,Настройки!$A$13:$A$16,0))+Настройки!$B$7*(R10-1),IF(R10=4,INDEX(Настройки!$C$13:$C$16,MATCH(C10,Настройки!$A$13:$A$16,0)),"Новый цикл"))) -> 0.84 | T10: =IF(OR(O10="",NOT(ISNUMBER(S10))),"",IF(N10="Т на С с низкими %",(INDEX(Настройки!$B$13:$B$16,2)+Настройки!$B$7*(MIN(R10,3)-1))-Настройки!$B$40,IF(N10="Лёгкий день",MIN(S10,(INDEX(Настройки!$B$13:$B$16,3)+Настройки!$B$7*(MIN(R10,3)-1)))-IF(C10="Л",M10,0),S10-M10))) -> 0.84 | U10: =IF(ISNUMBER(T10),ROUND(Настройки!$B$5*T10/Настройки!$B$6,0)*Настройки!$B$6,"") -> 137.5 | V10: =IF(O10="","",IF(NOT(ISNUMBER(S10)),S10,IF(O10="Л",INDEX(Настройки!$D$13:$G$16,3,MIN(R10,4)),INDEX(Настройки!$D$13:$G$16,MATCH(O10,Настройки!$A$13:$A$16,0),MIN(R10,4)))&IF(M10>0," (подходов не меньше 4)",""))) -> 5 по 3 | Z10: =IF(AND(N(W10)>0,N(X10)>0,N(X10)+N(Y10)<=10),W10*(1+(X10+N(Y10))/30),"") | AA10: =IF(Z10="","",Z10/Настройки!$B$5-1) | AB10: =IF(AA10="",AB9,AA10) | AC10: =IF(C10="","",TRIM(IF(AND(P10=1,COUNTIFS($B$4:$B$27,B10-1,$P$4:$P$27,1)>0),"Две поправки подряд: проверить ПМ или разгрузка. ","")&IF(AA10="","",IF(AND(AA10>Настройки!$B$41,N(AB9)>Настройки!$B$41),"ПМ выше расчёта 2 раза: обновить ПМ. ",IF(AND(AA10<-Настройки!$B$41,N(AB9)<-Настройки!$B$41),"ПМ ниже расчёта 2 раза: проверить ПМ. ","")))))
B11: =IF(7<6*IF(Настройки!$B$8="С-Л-Т",3,4),INT(7/IF(Настройки!$B$8="С-Л-Т",3,4))+1,"") -> 3 | C11: =IF(B11="","",IF(Настройки!$B$8="С-Л-Т",CHOOSE(MOD(7,3)+1,"С","Л","Т"),CHOOSE(MOD(7,4)+1,"М","С","Л","Т"))) -> Л | J11: =IF(D11="","",LOOKUP(D11,Настройки!$A$21:$A$24,Настройки!$B$21:$B$24)) | K11: =IF(OR(D11="",C11=""),0,LOOKUP(D11,Настройки!$A$21:$A$24,INDEX(Настройки!$C$21:$F$24,0,MATCH(C11,Настройки!$A$13:$A$16,0)))) -> 0 | L11: =IF(E11="",0,LOOKUP(E11,Настройки!$A$29:$A$33,Настройки!$B$29:$B$33))+IF(F11="",0,LOOKUP(F11,Настройки!$A$29:$A$33,Настройки!$B$29:$B$33))+IF(G11="",0,LOOKUP(G11,Настройки!$A$29:$A$33,Настройки!$B$29:$B$33)) -> 0 | M11: =MIN(Настройки!$B$37,K11+L11) -> 0 | N11: =IF(C11="","",IF(H11="да","Пропуск: инфекция",IF(I11="да","К тренеру, не тренироваться",IF(OR(IF(D11="","Нет",LOOKUP(D11,Настройки!$A$21:$A$24,Настройки!$G$21:$G$24))="Только Л",M11>=Настройки!$B$39),"Лёгкий день",IF(AND(C11="Т",OR(IF(D11="","Нет",LOOKUP(D11,Настройки!$A$21:$A$24,Настройки!$G$21:$G$24))="Т на С",M11>=Настройки!$B$38)),"Т на С с низкими %",IF(M11>0,"Снижение","По плану")))))) -> По плану | O11: =IF(C11="","",IF(LEFT(N11,6)="Пропус","",IF(N11="К тренеру, не тренироваться","",IF(N11="Лёгкий день","Л",IF(N11="Т на С с низкими %","С",C11))))) -> Л | P11: =IF(OR(N11="",N11="По плану"),0,1) -> 0 | Q11: =COUNTIFS($C$4:C10,C11,$P$4:P10,1) -> 0 | R11: =IF(B11="","",MAX(1,B11-Q11)) -> 3 | S11: =IF(C11="","",IF(R11<=3,INDEX(Настройки!$B$13:$B$16,MATCH(C11,Настройки!$A$13:$A$16,0))+Настройки!$B$7*(R11-1),IF(R11=4,INDEX(Настройки!$C$13:$C$16,MATCH(C11,Настройки!$A$13:$A$16,0)),"Новый цикл"))) -> 0.65 | T11: =IF(OR(O11="",NOT(ISNUMBER(S11))),"",IF(N11="Т на С с низкими %",(INDEX(Настройки!$B$13:$B$16,2)+Настройки!$B$7*(MIN(R11,3)-1))-Настройки!$B$40,IF(N11="Лёгкий день",MIN(S11,(INDEX(Настройки!$B$13:$B$16,3)+Настройки!$B$7*(MIN(R11,3)-1)))-IF(C11="Л",M11,0),S11-M11))) -> 0.65 | U11: =IF(ISNUMBER(T11),ROUND(Настройки!$B$5*T11/Настройки!$B$6,0)*Настройки!$B$6,"") -> 107.5 | V11: =IF(O11="","",IF(NOT(ISNUMBER(S11)),S11,IF(O11="Л",INDEX(Настройки!$D$13:$G$16,3,MIN(R11,4)),INDEX(Настройки!$D$13:$G$16,MATCH(O11,Настройки!$A$13:$A$16,0),MIN(R11,4)))&IF(M11>0," (подходов не меньше 4)",""))) -> 4 по 6 | Z11: =IF(AND(N(W11)>0,N(X11)>0,N(X11)+N(Y11)<=10),W11*(1+(X11+N(Y11))/30),"") | AA11: =IF(Z11="","",Z11/Настройки!$B$5-1) | AB11: =IF(AA11="",AB10,AA11) | AC11: =IF(C11="","",TRIM(IF(AND(P11=1,COUNTIFS($B$4:$B$27,B11-1,$P$4:$P$27,1)>0),"Две поправки подряд: проверить ПМ или разгрузка. ","")&IF(AA11="","",IF(AND(AA11>Настройки!$B$41,N(AB10)>Настройки!$B$41),"ПМ выше расчёта 2 раза: обновить ПМ. ",IF(AND(AA11<-Настройки!$B$41,N(AB10)<-Настройки!$B$41),"ПМ ниже расчёта 2 раза: проверить ПМ. ","")))))
B12: =IF(8<6*IF(Настройки!$B$8="С-Л-Т",3,4),INT(8/IF(Настройки!$B$8="С-Л-Т",3,4))+1,"") -> 3 | C12: =IF(B12="","",IF(Настройки!$B$8="С-Л-Т",CHOOSE(MOD(8,3)+1,"С","Л","Т"),CHOOSE(MOD(8,4)+1,"М","С","Л","Т"))) -> Т | J12: =IF(D12="","",LOOKUP(D12,Настройки!$A$21:$A$24,Настройки!$B$21:$B$24)) | K12: =IF(OR(D12="",C12=""),0,LOOKUP(D12,Настройки!$A$21:$A$24,INDEX(Настройки!$C$21:$F$24,0,MATCH(C12,Настройки!$A$13:$A$16,0)))) -> 0 | L12: =IF(E12="",0,LOOKUP(E12,Настройки!$A$29:$A$33,Настройки!$B$29:$B$33))+IF(F12="",0,LOOKUP(F12,Настройки!$A$29:$A$33,Настройки!$B$29:$B$33))+IF(G12="",0,LOOKUP(G12,Настройки!$A$29:$A$33,Настройки!$B$29:$B$33)) -> 0 | M12: =MIN(Настройки!$B$37,K12+L12) -> 0 | N12: =IF(C12="","",IF(H12="да","Пропуск: инфекция",IF(I12="да","К тренеру, не тренироваться",IF(OR(IF(D12="","Нет",LOOKUP(D12,Настройки!$A$21:$A$24,Настройки!$G$21:$G$24))="Только Л",M12>=Настройки!$B$39),"Лёгкий день",IF(AND(C12="Т",OR(IF(D12="","Нет",LOOKUP(D12,Настройки!$A$21:$A$24,Настройки!$G$21:$G$24))="Т на С",M12>=Настройки!$B$38)),"Т на С с низкими %",IF(M12>0,"Снижение","По плану")))))) -> По плану | O12: =IF(C12="","",IF(LEFT(N12,6)="Пропус","",IF(N12="К тренеру, не тренироваться","",IF(N12="Лёгкий день","Л",IF(N12="Т на С с низкими %","С",C12))))) -> Т | P12: =IF(OR(N12="",N12="По плану"),0,1) -> 0 | Q12: =COUNTIFS($C$4:C11,C12,$P$4:P11,1) -> 0 | R12: =IF(B12="","",MAX(1,B12-Q12)) -> 3 | S12: =IF(C12="","",IF(R12<=3,INDEX(Настройки!$B$13:$B$16,MATCH(C12,Настройки!$A$13:$A$16,0))+Настройки!$B$7*(R12-1),IF(R12=4,INDEX(Настройки!$C$13:$C$16,MATCH(C12,Настройки!$A$13:$A$16,0)),"Новый цикл"))) -> 1 | T12: =IF(OR(O12="",NOT(ISNUMBER(S12))),"",IF(N12="Т на С с низкими %",(INDEX(Настройки!$B$13:$B$16,2)+Настройки!$B$7*(MIN(R12,3)-1))-Настройки!$B$40,IF(N12="Лёгкий день",MIN(S12,(INDEX(Настройки!$B$13:$B$16,3)+Настройки!$B$7*(MIN(R12,3)-1)))-IF(C12="Л",M12,0),S12-M12))) -> 1 | U12: =IF(ISNUMBER(T12),ROUND(Настройки!$B$5*T12/Настройки!$B$6,0)*Настройки!$B$6,"") -> 165 | V12: =IF(O12="","",IF(NOT(ISNUMBER(S12)),S12,IF(O12="Л",INDEX(Настройки!$D$13:$G$16,3,MIN(R12,4)),INDEX(Настройки!$D$13:$G$16,MATCH(O12,Настройки!$A$13:$A$16,0),MIN(R12,4)))&IF(M12>0," (подходов не меньше 4)",""))) -> 3 по 1 + 92%, 2 по 2 | Z12: =IF(AND(N(W12)>0,N(X12)>0,N(X12)+N(Y12)<=10),W12*(1+(X12+N(Y12))/30),"") | AA12: =IF(Z12="","",Z12/Настройки!$B$5-1) | AB12: =IF(AA12="",AB11,AA12) | AC12: =IF(C12="","",TRIM(IF(AND(P12=1,COUNTIFS($B$4:$B$27,B12-1,$P$4:$P$27,1)>0),"Две поправки подряд: проверить ПМ или разгрузка. ","")&IF(AA12="","",IF(AND(AA12>Настройки!$B$41,N(AB11)>Настройки!$B$41),"ПМ выше расчёта 2 раза: обновить ПМ. ",IF(AND(AA12<-Настройки!$B$41,N(AB11)<-Настройки!$B$41),"ПМ ниже расчёта 2 раза: проверить ПМ. ","")))))
B13: =IF(9<6*IF(Настройки!$B$8="С-Л-Т",3,4),INT(9/IF(Настройки!$B$8="С-Л-Т",3,4))+1,"") -> 4 | C13: =IF(B13="","",IF(Настройки!$B$8="С-Л-Т",CHOOSE(MOD(9,3)+1,"С","Л","Т"),CHOOSE(MOD(9,4)+1,"М","С","Л","Т"))) -> С | J13: =IF(D13="","",LOOKUP(D13,Настройки!$A$21:$A$24,Настройки!$B$21:$B$24)) | K13: =IF(OR(D13="",C13=""),0,LOOKUP(D13,Настройки!$A$21:$A$24,INDEX(Настройки!$C$21:$F$24,0,MATCH(C13,Настройки!$A$13:$A$16,0)))) -> 0 | L13: =IF(E13="",0,LOOKUP(E13,Настройки!$A$29:$A$33,Настройки!$B$29:$B$33))+IF(F13="",0,LOOKUP(F13,Настройки!$A$29:$A$33,Настройки!$B$29:$B$33))+IF(G13="",0,LOOKUP(G13,Настройки!$A$29:$A$33,Настройки!$B$29:$B$33)) -> 0 | M13: =MIN(Настройки!$B$37,K13+L13) -> 0 | N13: =IF(C13="","",IF(H13="да","Пропуск: инфекция",IF(I13="да","К тренеру, не тренироваться",IF(OR(IF(D13="","Нет",LOOKUP(D13,Настройки!$A$21:$A$24,Настройки!$G$21:$G$24))="Только Л",M13>=Настройки!$B$39),"Лёгкий день",IF(AND(C13="Т",OR(IF(D13="","Нет",LOOKUP(D13,Настройки!$A$21:$A$24,Настройки!$G$21:$G$24))="Т на С",M13>=Настройки!$B$38)),"Т на С с низкими %",IF(M13>0,"Снижение","По плану")))))) -> По плану | O13: =IF(C13="","",IF(LEFT(N13,6)="Пропус","",IF(N13="К тренеру, не тренироваться","",IF(N13="Лёгкий день","Л",IF(N13="Т на С с низкими %","С",C13))))) -> С | P13: =IF(OR(N13="",N13="По плану"),0,1) -> 0 | Q13: =COUNTIFS($C$4:C12,C13,$P$4:P12,1) -> 1 | R13: =IF(B13="","",MAX(1,B13-Q13)) -> 3 | S13: =IF(C13="","",IF(R13<=3,INDEX(Настройки!$B$13:$B$16,MATCH(C13,Настройки!$A$13:$A$16,0))+Настройки!$B$7*(R13-1),IF(R13=4,INDEX(Настройки!$C$13:$C$16,MATCH(C13,Настройки!$A$13:$A$16,0)),"Новый цикл"))) -> 0.88 | T13: =IF(OR(O13="",NOT(ISNUMBER(S13))),"",IF(N13="Т на С с низкими %",(INDEX(Настройки!$B$13:$B$16,2)+Настройки!$B$7*(MIN(R13,3)-1))-Настройки!$B$40,IF(N13="Лёгкий день",MIN(S13,(INDEX(Настройки!$B$13:$B$16,3)+Настройки!$B$7*(MIN(R13,3)-1)))-IF(C13="Л",M13,0),S13-M13))) -> 0.88 | U13: =IF(ISNUMBER(T13),ROUND(Настройки!$B$5*T13/Настройки!$B$6,0)*Настройки!$B$6,"") -> 145 | V13: =IF(O13="","",IF(NOT(ISNUMBER(S13)),S13,IF(O13="Л",INDEX(Настройки!$D$13:$G$16,3,MIN(R13,4)),INDEX(Настройки!$D$13:$G$16,MATCH(O13,Настройки!$A$13:$A$16,0),MIN(R13,4)))&IF(M13>0," (подходов не меньше 4)",""))) -> 7 по 2 | Z13: =IF(AND(N(W13)>0,N(X13)>0,N(X13)+N(Y13)<=10),W13*(1+(X13+N(Y13))/30),"") | AA13: =IF(Z13="","",Z13/Настройки!$B$5-1) | AB13: =IF(AA13="",AB12,AA13) | AC13: =IF(C13="","",TRIM(IF(AND(P13=1,COUNTIFS($B$4:$B$27,B13-1,$P$4:$P$27,1)>0),"Две поправки подряд: проверить ПМ или разгрузка. ","")&IF(AA13="","",IF(AND(AA13>Настройки!$B$41,N(AB12)>Настройки!$B$41),"ПМ выше расчёта 2 раза: обновить ПМ. ",IF(AND(AA13<-Настройки!$B$41,N(AB12)<-Настройки!$B$41),"ПМ ниже расчёта 2 раза: проверить ПМ. ","")))))
B14: =IF(10<6*IF(Настройки!$B$8="С-Л-Т",3,4),INT(10/IF(Настройки!$B$8="С-Л-Т",3,4))+1,"") -> 4 | C14: =IF(B14="","",IF(Настройки!$B$8="С-Л-Т",CHOOSE(MOD(10,3)+1,"С","Л","Т"),CHOOSE(MOD(10,4)+1,"М","С","Л","Т"))) -> Л | J14: =IF(D14="","",LOOKUP(D14,Настройки!$A$21:$A$24,Настройки!$B$21:$B$24)) | K14: =IF(OR(D14="",C14=""),0,LOOKUP(D14,Настройки!$A$21:$A$24,INDEX(Настройки!$C$21:$F$24,0,MATCH(C14,Настройки!$A$13:$A$16,0)))) -> 0 | L14: =IF(E14="",0,LOOKUP(E14,Настройки!$A$29:$A$33,Настройки!$B$29:$B$33))+IF(F14="",0,LOOKUP(F14,Настройки!$A$29:$A$33,Настройки!$B$29:$B$33))+IF(G14="",0,LOOKUP(G14,Настройки!$A$29:$A$33,Настройки!$B$29:$B$33)) -> 0 | M14: =MIN(Настройки!$B$37,K14+L14) -> 0 | N14: =IF(C14="","",IF(H14="да","Пропуск: инфекция",IF(I14="да","К тренеру, не тренироваться",IF(OR(IF(D14="","Нет",LOOKUP(D14,Настройки!$A$21:$A$24,Настройки!$G$21:$G$24))="Только Л",M14>=Настройки!$B$39),"Лёгкий день",IF(AND(C14="Т",OR(IF(D14="","Нет",LOOKUP(D14,Настройки!$A$21:$A$24,Настройки!$G$21:$G$24))="Т на С",M14>=Настройки!$B$38)),"Т на С с низкими %",IF(M14>0,"Снижение","По плану")))))) -> По плану | O14: =IF(C14="","",IF(LEFT(N14,6)="Пропус","",IF(N14="К тренеру, не тренироваться","",IF(N14="Лёгкий день","Л",IF(N14="Т на С с низкими %","С",C14))))) -> Л | P14: =IF(OR(N14="",N14="По плану"),0,1) -> 0 | Q14: =COUNTIFS($C$4:C13,C14,$P$4:P13,1) -> 0 | R14: =IF(B14="","",MAX(1,B14-Q14)) -> 4 | S14: =IF(C14="","",IF(R14<=3,INDEX(Настройки!$B$13:$B$16,MATCH(C14,Настройки!$A$13:$A$16,0))+Настройки!$B$7*(R14-1),IF(R14=4,INDEX(Настройки!$C$13:$C$16,MATCH(C14,Настройки!$A$13:$A$16,0)),"Новый цикл"))) -> 0.57 | T14: =IF(OR(O14="",NOT(ISNUMBER(S14))),"",IF(N14="Т на С с низкими %",(INDEX(Настройки!$B$13:$B$16,2)+Настройки!$B$7*(MIN(R14,3)-1))-Настройки!$B$40,IF(N14="Лёгкий день",MIN(S14,(INDEX(Настройки!$B$13:$B$16,3)+Настройки!$B$7*(MIN(R14,3)-1)))-IF(C14="Л",M14,0),S14-M14))) -> 0.57 | U14: =IF(ISNUMBER(T14),ROUND(Настройки!$B$5*T14/Настройки!$B$6,0)*Настройки!$B$6,"") -> 95 | V14: =IF(O14="","",IF(NOT(ISNUMBER(S14)),S14,IF(O14="Л",INDEX(Настройки!$D$13:$G$16,3,MIN(R14,4)),INDEX(Настройки!$D$13:$G$16,MATCH(O14,Настройки!$A$13:$A$16,0),MIN(R14,4)))&IF(M14>0," (подходов не меньше 4)",""))) -> 4 по 3 | Z14: =IF(AND(N(W14)>0,N(X14)>0,N(X14)+N(Y14)<=10),W14*(1+(X14+N(Y14))/30),"") | AA14: =IF(Z14="","",Z14/Настройки!$B$5-1) | AB14: =IF(AA14="",AB13,AA14) | AC14: =IF(C14="","",TRIM(IF(AND(P14=1,COUNTIFS($B$4:$B$27,B14-1,$P$4:$P$27,1)>0),"Две поправки подряд: проверить ПМ или разгрузка. ","")&IF(AA14="","",IF(AND(AA14>Настройки!$B$41,N(AB13)>Настройки!$B$41),"ПМ выше расчёта 2 раза: обновить ПМ. ",IF(AND(AA14<-Настройки!$B$41,N(AB13)<-Настройки!$B$41),"ПМ ниже расчёта 2 раза: проверить ПМ. ","")))))
B15: =IF(11<6*IF(Настройки!$B$8="С-Л-Т",3,4),INT(11/IF(Настройки!$B$8="С-Л-Т",3,4))+1,"") -> 4 | C15: =IF(B15="","",IF(Настройки!$B$8="С-Л-Т",CHOOSE(MOD(11,3)+1,"С","Л","Т"),CHOOSE(MOD(11,4)+1,"М","С","Л","Т"))) -> Т | J15: =IF(D15="","",LOOKUP(D15,Настройки!$A$21:$A$24,Настройки!$B$21:$B$24)) | K15: =IF(OR(D15="",C15=""),0,LOOKUP(D15,Настройки!$A$21:$A$24,INDEX(Настройки!$C$21:$F$24,0,MATCH(C15,Настройки!$A$13:$A$16,0)))) -> 0 | L15: =IF(E15="",0,LOOKUP(E15,Настройки!$A$29:$A$33,Настройки!$B$29:$B$33))+IF(F15="",0,LOOKUP(F15,Настройки!$A$29:$A$33,Настройки!$B$29:$B$33))+IF(G15="",0,LOOKUP(G15,Настройки!$A$29:$A$33,Настройки!$B$29:$B$33)) -> 0 | M15: =MIN(Настройки!$B$37,K15+L15) -> 0 | N15: =IF(C15="","",IF(H15="да","Пропуск: инфекция",IF(I15="да","К тренеру, не тренироваться",IF(OR(IF(D15="","Нет",LOOKUP(D15,Настройки!$A$21:$A$24,Настройки!$G$21:$G$24))="Только Л",M15>=Настройки!$B$39),"Лёгкий день",IF(AND(C15="Т",OR(IF(D15="","Нет",LOOKUP(D15,Настройки!$A$21:$A$24,Настройки!$G$21:$G$24))="Т на С",M15>=Настройки!$B$38)),"Т на С с низкими %",IF(M15>0,"Снижение","По плану")))))) -> По плану | O15: =IF(C15="","",IF(LEFT(N15,6)="Пропус","",IF(N15="К тренеру, не тренироваться","",IF(N15="Лёгкий день","Л",IF(N15="Т на С с низкими %","С",C15))))) -> Т | P15: =IF(OR(N15="",N15="По плану"),0,1) -> 0 | Q15: =COUNTIFS($C$4:C14,C15,$P$4:P14,1) -> 0 | R15: =IF(B15="","",MAX(1,B15-Q15)) -> 4 | S15: =IF(C15="","",IF(R15<=3,INDEX(Настройки!$B$13:$B$16,MATCH(C15,Настройки!$A$13:$A$16,0))+Настройки!$B$7*(R15-1),IF(R15=4,INDEX(Настройки!$C$13:$C$16,MATCH(C15,Настройки!$A$13:$A$16,0)),"Новый цикл"))) -> Проходка | T15: =IF(OR(O15="",NOT(ISNUMBER(S15))),"",IF(N15="Т на С с низкими %",(INDEX(Настройки!$B$13:$B$16,2)+Настройки!$B$7*(MIN(R15,3)-1))-Настройки!$B$40,IF(N15="Лёгкий день",MIN(S15,(INDEX(Настройки!$B$13:$B$16,3)+Настройки!$B$7*(MIN(R15,3)-1)))-IF(C15="Л",M15,0),S15-M15))) | U15: =IF(ISNUMBER(T15),ROUND(Настройки!$B$5*T15/Настройки!$B$6,0)*Настройки!$B$6,"") | V15: =IF(O15="","",IF(NOT(ISNUMBER(S15)),S15,IF(O15="Л",INDEX(Настройки!$D$13:$G$16,3,MIN(R15,4)),INDEX(Настройки!$D$13:$G$16,MATCH(O15,Настройки!$A$13:$A$16,0),MIN(R15,4)))&IF(M15>0," (подходов не меньше 4)",""))) -> Проходка | Z15: =IF(AND(N(W15)>0,N(X15)>0,N(X15)+N(Y15)<=10),W15*(1+(X15+N(Y15))/30),"") | AA15: =IF(Z15="","",Z15/Настройки!$B$5-1) | AB15: =IF(AA15="",AB14,AA15) | AC15: =IF(C15="","",TRIM(IF(AND(P15=1,COUNTIFS($B$4:$B$27,B15-1,$P$4:$P$27,1)>0),"Две поправки подряд: проверить ПМ или разгрузка. ","")&IF(AA15="","",IF(AND(AA15>Настройки!$B$41,N(AB14)>Настройки!$B$41),"ПМ выше расчёта 2 раза: обновить ПМ. ",IF(AND(AA15<-Настройки!$B$41,N(AB14)<-Настройки!$B$41),"ПМ ниже расчёта 2 раза: проверить ПМ. ","")))))
B16: =IF(12<6*IF(Настройки!$B$8="С-Л-Т",3,4),INT(12/IF(Настройки!$B$8="С-Л-Т",3,4))+1,"") -> 5 | C16: =IF(B16="","",IF(Настройки!$B$8="С-Л-Т",CHOOSE(MOD(12,3)+1,"С","Л","Т"),CHOOSE(MOD(12,4)+1,"М","С","Л","Т"))) -> С | J16: =IF(D16="","",LOOKUP(D16,Настройки!$A$21:$A$24,Настройки!$B$21:$B$24)) | K16: =IF(OR(D16="",C16=""),0,LOOKUP(D16,Настройки!$A$21:$A$24,INDEX(Настройки!$C$21:$F$24,0,MATCH(C16,Настройки!$A$13:$A$16,0)))) -> 0 | L16: =IF(E16="",0,LOOKUP(E16,Настройки!$A$29:$A$33,Настройки!$B$29:$B$33))+IF(F16="",0,LOOKUP(F16,Настройки!$A$29:$A$33,Настройки!$B$29:$B$33))+IF(G16="",0,LOOKUP(G16,Настройки!$A$29:$A$33,Настройки!$B$29:$B$33)) -> 0 | M16: =MIN(Настройки!$B$37,K16+L16) -> 0 | N16: =IF(C16="","",IF(H16="да","Пропуск: инфекция",IF(I16="да","К тренеру, не тренироваться",IF(OR(IF(D16="","Нет",LOOKUP(D16,Настройки!$A$21:$A$24,Настройки!$G$21:$G$24))="Только Л",M16>=Настройки!$B$39),"Лёгкий день",IF(AND(C16="Т",OR(IF(D16="","Нет",LOOKUP(D16,Настройки!$A$21:$A$24,Настройки!$G$21:$G$24))="Т на С",M16>=Настройки!$B$38)),"Т на С с низкими %",IF(M16>0,"Снижение","По плану")))))) -> По плану | O16: =IF(C16="","",IF(LEFT(N16,6)="Пропус","",IF(N16="К тренеру, не тренироваться","",IF(N16="Лёгкий день","Л",IF(N16="Т на С с низкими %","С",C16))))) -> С | P16: =IF(OR(N16="",N16="По плану"),0,1) -> 0 | Q16: =COUNTIFS($C$4:C15,C16,$P$4:P15,1) -> 1 | R16: =IF(B16="","",MAX(1,B16-Q16)) -> 4 | S16: =IF(C16="","",IF(R16<=3,INDEX(Настройки!$B$13:$B$16,MATCH(C16,Настройки!$A$13:$A$16,0))+Настройки!$B$7*(R16-1),IF(R16=4,INDEX(Настройки!$C$13:$C$16,MATCH(C16,Настройки!$A$13:$A$16,0)),"Новый цикл"))) -> 0.8 | T16: =IF(OR(O16="",NOT(ISNUMBER(S16))),"",IF(N16="Т на С с низкими %",(INDEX(Настройки!$B$13:$B$16,2)+Настройки!$B$7*(MIN(R16,3)-1))-Настройки!$B$40,IF(N16="Лёгкий день",MIN(S16,(INDEX(Настройки!$B$13:$B$16,3)+Настройки!$B$7*(MIN(R16,3)-1)))-IF(C16="Л",M16,0),S16-M16))) -> 0.8 | U16: =IF(ISNUMBER(T16),ROUND(Настройки!$B$5*T16/Настройки!$B$6,0)*Настройки!$B$6,"") -> 132.5 | V16: =IF(O16="","",IF(NOT(ISNUMBER(S16)),S16,IF(O16="Л",INDEX(Настройки!$D$13:$G$16,3,MIN(R16,4)),INDEX(Настройки!$D$13:$G$16,MATCH(O16,Настройки!$A$13:$A$16,0),MIN(R16,4)))&IF(M16>0," (подходов не меньше 4)",""))) -> 4 по 2 | Z16: =IF(AND(N(W16)>0,N(X16)>0,N(X16)+N(Y16)<=10),W16*(1+(X16+N(Y16))/30),"") | AA16: =IF(Z16="","",Z16/Настройки!$B$5-1) | AB16: =IF(AA16="",AB15,AA16) | AC16: =IF(C16="","",TRIM(IF(AND(P16=1,COUNTIFS($B$4:$B$27,B16-1,$P$4:$P$27,1)>0),"Две поправки подряд: проверить ПМ или разгрузка. ","")&IF(AA16="","",IF(AND(AA16>Настройки!$B$41,N(AB15)>Настройки!$B$41),"ПМ выше расчёта 2 раза: обновить ПМ. ",IF(AND(AA16<-Настройки!$B$41,N(AB15)<-Настройки!$B$41),"ПМ ниже расчёта 2 раза: проверить ПМ. ","")))))
B17: =IF(13<6*IF(Настройки!$B$8="С-Л-Т",3,4),INT(13/IF(Настройки!$B$8="С-Л-Т",3,4))+1,"") -> 5 | C17: =IF(B17="","",IF(Настройки!$B$8="С-Л-Т",CHOOSE(MOD(13,3)+1,"С","Л","Т"),CHOOSE(MOD(13,4)+1,"М","С","Л","Т"))) -> Л | J17: =IF(D17="","",LOOKUP(D17,Настройки!$A$21:$A$24,Настройки!$B$21:$B$24)) | K17: =IF(OR(D17="",C17=""),0,LOOKUP(D17,Настройки!$A$21:$A$24,INDEX(Настройки!$C$21:$F$24,0,MATCH(C17,Настройки!$A$13:$A$16,0)))) -> 0 | L17: =IF(E17="",0,LOOKUP(E17,Настройки!$A$29:$A$33,Настройки!$B$29:$B$33))+IF(F17="",0,LOOKUP(F17,Настройки!$A$29:$A$33,Настройки!$B$29:$B$33))+IF(G17="",0,LOOKUP(G17,Настройки!$A$29:$A$33,Настройки!$B$29:$B$33)) -> 0 | M17: =MIN(Настройки!$B$37,K17+L17) -> 0 | N17: =IF(C17="","",IF(H17="да","Пропуск: инфекция",IF(I17="да","К тренеру, не тренироваться",IF(OR(IF(D17="","Нет",LOOKUP(D17,Настройки!$A$21:$A$24,Настройки!$G$21:$G$24))="Только Л",M17>=Настройки!$B$39),"Лёгкий день",IF(AND(C17="Т",OR(IF(D17="","Нет",LOOKUP(D17,Настройки!$A$21:$A$24,Настройки!$G$21:$G$24))="Т на С",M17>=Настройки!$B$38)),"Т на С с низкими %",IF(M17>0,"Снижение","По плану")))))) -> По плану | O17: =IF(C17="","",IF(LEFT(N17,6)="Пропус","",IF(N17="К тренеру, не тренироваться","",IF(N17="Лёгкий день","Л",IF(N17="Т на С с низкими %","С",C17))))) -> Л | P17: =IF(OR(N17="",N17="По плану"),0,1) -> 0 | Q17: =COUNTIFS($C$4:C16,C17,$P$4:P16,1) -> 0 | R17: =IF(B17="","",MAX(1,B17-Q17)) -> 5 | S17: =IF(C17="","",IF(R17<=3,INDEX(Настройки!$B$13:$B$16,MATCH(C17,Настройки!$A$13:$A$16,0))+Настройки!$B$7*(R17-1),IF(R17=4,INDEX(Настройки!$C$13:$C$16,MATCH(C17,Настройки!$A$13:$A$16,0)),"Новый цикл"))) -> Новый цикл | T17: =IF(OR(O17="",NOT(ISNUMBER(S17))),"",IF(N17="Т на С с низкими %",(INDEX(Настройки!$B$13:$B$16,2)+Настройки!$B$7*(MIN(R17,3)-1))-Настройки!$B$40,IF(N17="Лёгкий день",MIN(S17,(INDEX(Настройки!$B$13:$B$16,3)+Настройки!$B$7*(MIN(R17,3)-1)))-IF(C17="Л",M17,0),S17-M17))) | U17: =IF(ISNUMBER(T17),ROUND(Настройки!$B$5*T17/Настройки!$B$6,0)*Настройки!$B$6,"") | V17: =IF(O17="","",IF(NOT(ISNUMBER(S17)),S17,IF(O17="Л",INDEX(Настройки!$D$13:$G$16,3,MIN(R17,4)),INDEX(Настройки!$D$13:$G$16,MATCH(O17,Настройки!$A$13:$A$16,0),MIN(R17,4)))&IF(M17>0," (подходов не меньше 4)",""))) -> Новый цикл | Z17: =IF(AND(N(W17)>0,N(X17)>0,N(X17)+N(Y17)<=10),W17*(1+(X17+N(Y17))/30),"") | AA17: =IF(Z17="","",Z17/Настройки!$B$5-1) | AB17: =IF(AA17="",AB16,AA17) | AC17: =IF(C17="","",TRIM(IF(AND(P17=1,COUNTIFS($B$4:$B$27,B17-1,$P$4:$P$27,1)>0),"Две поправки подряд: проверить ПМ или разгрузка. ","")&IF(AA17="","",IF(AND(AA17>Настройки!$B$41,N(AB16)>Настройки!$B$41),"ПМ выше расчёта 2 раза: обновить ПМ. ",IF(AND(AA17<-Настройки!$B$41,N(AB16)<-Настройки!$B$41),"ПМ ниже расчёта 2 раза: проверить ПМ. ","")))))
B18: =IF(14<6*IF(Настройки!$B$8="С-Л-Т",3,4),INT(14/IF(Настройки!$B$8="С-Л-Т",3,4))+1,"") -> 5 | C18: =IF(B18="","",IF(Настройки!$B$8="С-Л-Т",CHOOSE(MOD(14,3)+1,"С","Л","Т"),CHOOSE(MOD(14,4)+1,"М","С","Л","Т"))) -> Т | J18: =IF(D18="","",LOOKUP(D18,Настройки!$A$21:$A$24,Настройки!$B$21:$B$24)) | K18: =IF(OR(D18="",C18=""),0,LOOKUP(D18,Настройки!$A$21:$A$24,INDEX(Настройки!$C$21:$F$24,0,MATCH(C18,Настройки!$A$13:$A$16,0)))) -> 0 | L18: =IF(E18="",0,LOOKUP(E18,Настройки!$A$29:$A$33,Настройки!$B$29:$B$33))+IF(F18="",0,LOOKUP(F18,Настройки!$A$29:$A$33,Настройки!$B$29:$B$33))+IF(G18="",0,LOOKUP(G18,Настройки!$A$29:$A$33,Настройки!$B$29:$B$33)) -> 0 | M18: =MIN(Настройки!$B$37,K18+L18) -> 0 | N18: =IF(C18="","",IF(H18="да","Пропуск: инфекция",IF(I18="да","К тренеру, не тренироваться",IF(OR(IF(D18="","Нет",LOOKUP(D18,Настройки!$A$21:$A$24,Настройки!$G$21:$G$24))="Только Л",M18>=Настройки!$B$39),"Лёгкий день",IF(AND(C18="Т",OR(IF(D18="","Нет",LOOKUP(D18,Настройки!$A$21:$A$24,Настройки!$G$21:$G$24))="Т на С",M18>=Настройки!$B$38)),"Т на С с низкими %",IF(M18>0,"Снижение","По плану")))))) -> По плану | O18: =IF(C18="","",IF(LEFT(N18,6)="Пропус","",IF(N18="К тренеру, не тренироваться","",IF(N18="Лёгкий день","Л",IF(N18="Т на С с низкими %","С",C18))))) -> Т | P18: =IF(OR(N18="",N18="По плану"),0,1) -> 0 | Q18: =COUNTIFS($C$4:C17,C18,$P$4:P17,1) -> 0 | R18: =IF(B18="","",MAX(1,B18-Q18)) -> 5 | S18: =IF(C18="","",IF(R18<=3,INDEX(Настройки!$B$13:$B$16,MATCH(C18,Настройки!$A$13:$A$16,0))+Настройки!$B$7*(R18-1),IF(R18=4,INDEX(Настройки!$C$13:$C$16,MATCH(C18,Настройки!$A$13:$A$16,0)),"Новый цикл"))) -> Новый цикл | T18: =IF(OR(O18="",NOT(ISNUMBER(S18))),"",IF(N18="Т на С с низкими %",(INDEX(Настройки!$B$13:$B$16,2)+Настройки!$B$7*(MIN(R18,3)-1))-Настройки!$B$40,IF(N18="Лёгкий день",MIN(S18,(INDEX(Настройки!$B$13:$B$16,3)+Настройки!$B$7*(MIN(R18,3)-1)))-IF(C18="Л",M18,0),S18-M18))) | U18: =IF(ISNUMBER(T18),ROUND(Настройки!$B$5*T18/Настройки!$B$6,0)*Настройки!$B$6,"") | V18: =IF(O18="","",IF(NOT(ISNUMBER(S18)),S18,IF(O18="Л",INDEX(Настройки!$D$13:$G$16,3,MIN(R18,4)),INDEX(Настройки!$D$13:$G$16,MATCH(O18,Настройки!$A$13:$A$16,0),MIN(R18,4)))&IF(M18>0," (подходов не меньше 4)",""))) -> Новый цикл | Z18: =IF(AND(N(W18)>0,N(X18)>0,N(X18)+N(Y18)<=10),W18*(1+(X18+N(Y18))/30),"") | AA18: =IF(Z18="","",Z18/Настройки!$B$5-1) | AB18: =IF(AA18="",AB17,AA18) | AC18: =IF(C18="","",TRIM(IF(AND(P18=1,COUNTIFS($B$4:$B$27,B18-1,$P$4:$P$27,1)>0),"Две поправки подряд: проверить ПМ или разгрузка. ","")&IF(AA18="","",IF(AND(AA18>Настройки!$B$41,N(AB17)>Настройки!$B$41),"ПМ выше расчёта 2 раза: обновить ПМ. ",IF(AND(AA18<-Настройки!$B$41,N(AB17)<-Настройки!$B$41),"ПМ ниже расчёта 2 раза: проверить ПМ. ","")))))
B19: =IF(15<6*IF(Настройки!$B$8="С-Л-Т",3,4),INT(15/IF(Настройки!$B$8="С-Л-Т",3,4))+1,"") -> 6 | C19: =IF(B19="","",IF(Настройки!$B$8="С-Л-Т",CHOOSE(MOD(15,3)+1,"С","Л","Т"),CHOOSE(MOD(15,4)+1,"М","С","Л","Т"))) -> С | J19: =IF(D19="","",LOOKUP(D19,Настройки!$A$21:$A$24,Настройки!$B$21:$B$24)) | K19: =IF(OR(D19="",C19=""),0,LOOKUP(D19,Настройки!$A$21:$A$24,INDEX(Настройки!$C$21:$F$24,0,MATCH(C19,Настройки!$A$13:$A$16,0)))) -> 0 | L19: =IF(E19="",0,LOOKUP(E19,Настройки!$A$29:$A$33,Настройки!$B$29:$B$33))+IF(F19="",0,LOOKUP(F19,Настройки!$A$29:$A$33,Настройки!$B$29:$B$33))+IF(G19="",0,LOOKUP(G19,Настройки!$A$29:$A$33,Настройки!$B$29:$B$33)) -> 0 | M19: =MIN(Настройки!$B$37,K19+L19) -> 0 | N19: =IF(C19="","",IF(H19="да","Пропуск: инфекция",IF(I19="да","К тренеру, не тренироваться",IF(OR(IF(D19="","Нет",LOOKUP(D19,Настройки!$A$21:$A$24,Настройки!$G$21:$G$24))="Только Л",M19>=Настройки!$B$39),"Лёгкий день",IF(AND(C19="Т",OR(IF(D19="","Нет",LOOKUP(D19,Настройки!$A$21:$A$24,Настройки!$G$21:$G$24))="Т на С",M19>=Настройки!$B$38)),"Т на С с низкими %",IF(M19>0,"Снижение","По плану")))))) -> По плану | O19: =IF(C19="","",IF(LEFT(N19,6)="Пропус","",IF(N19="К тренеру, не тренироваться","",IF(N19="Лёгкий день","Л",IF(N19="Т на С с низкими %","С",C19))))) -> С | P19: =IF(OR(N19="",N19="По плану"),0,1) -> 0 | Q19: =COUNTIFS($C$4:C18,C19,$P$4:P18,1) -> 1 | R19: =IF(B19="","",MAX(1,B19-Q19)) -> 5 | S19: =IF(C19="","",IF(R19<=3,INDEX(Настройки!$B$13:$B$16,MATCH(C19,Настройки!$A$13:$A$16,0))+Настройки!$B$7*(R19-1),IF(R19=4,INDEX(Настройки!$C$13:$C$16,MATCH(C19,Настройки!$A$13:$A$16,0)),"Новый цикл"))) -> Новый цикл | T19: =IF(OR(O19="",NOT(ISNUMBER(S19))),"",IF(N19="Т на С с низкими %",(INDEX(Настройки!$B$13:$B$16,2)+Настройки!$B$7*(MIN(R19,3)-1))-Настройки!$B$40,IF(N19="Лёгкий день",MIN(S19,(INDEX(Настройки!$B$13:$B$16,3)+Настройки!$B$7*(MIN(R19,3)-1)))-IF(C19="Л",M19,0),S19-M19))) | U19: =IF(ISNUMBER(T19),ROUND(Настройки!$B$5*T19/Настройки!$B$6,0)*Настройки!$B$6,"") | V19: =IF(O19="","",IF(NOT(ISNUMBER(S19)),S19,IF(O19="Л",INDEX(Настройки!$D$13:$G$16,3,MIN(R19,4)),INDEX(Настройки!$D$13:$G$16,MATCH(O19,Настройки!$A$13:$A$16,0),MIN(R19,4)))&IF(M19>0," (подходов не меньше 4)",""))) -> Новый цикл | Z19: =IF(AND(N(W19)>0,N(X19)>0,N(X19)+N(Y19)<=10),W19*(1+(X19+N(Y19))/30),"") | AA19: =IF(Z19="","",Z19/Настройки!$B$5-1) | AB19: =IF(AA19="",AB18,AA19) | AC19: =IF(C19="","",TRIM(IF(AND(P19=1,COUNTIFS($B$4:$B$27,B19-1,$P$4:$P$27,1)>0),"Две поправки подряд: проверить ПМ или разгрузка. ","")&IF(AA19="","",IF(AND(AA19>Настройки!$B$41,N(AB18)>Настройки!$B$41),"ПМ выше расчёта 2 раза: обновить ПМ. ",IF(AND(AA19<-Настройки!$B$41,N(AB18)<-Настройки!$B$41),"ПМ ниже расчёта 2 раза: проверить ПМ. ","")))))
B20: =IF(16<6*IF(Настройки!$B$8="С-Л-Т",3,4),INT(16/IF(Настройки!$B$8="С-Л-Т",3,4))+1,"") -> 6 | C20: =IF(B20="","",IF(Настройки!$B$8="С-Л-Т",CHOOSE(MOD(16,3)+1,"С","Л","Т"),CHOOSE(MOD(16,4)+1,"М","С","Л","Т"))) -> Л | J20: =IF(D20="","",LOOKUP(D20,Настройки!$A$21:$A$24,Настройки!$B$21:$B$24)) | K20: =IF(OR(D20="",C20=""),0,LOOKUP(D20,Настройки!$A$21:$A$24,INDEX(Настройки!$C$21:$F$24,0,MATCH(C20,Настройки!$A$13:$A$16,0)))) -> 0 | L20: =IF(E20="",0,LOOKUP(E20,Настройки!$A$29:$A$33,Настройки!$B$29:$B$33))+IF(F20="",0,LOOKUP(F20,Настройки!$A$29:$A$33,Настройки!$B$29:$B$33))+IF(G20="",0,LOOKUP(G20,Настройки!$A$29:$A$33,Настройки!$B$29:$B$33)) -> 0 | M20: =MIN(Настройки!$B$37,K20+L20) -> 0 | N20: =IF(C20="","",IF(H20="да","Пропуск: инфекция",IF(I20="да","К тренеру, не тренироваться",IF(OR(IF(D20="","Нет",LOOKUP(D20,Настройки!$A$21:$A$24,Настройки!$G$21:$G$24))="Только Л",M20>=Настройки!$B$39),"Лёгкий день",IF(AND(C20="Т",OR(IF(D20="","Нет",LOOKUP(D20,Настройки!$A$21:$A$24,Настройки!$G$21:$G$24))="Т на С",M20>=Настройки!$B$38)),"Т на С с низкими %",IF(M20>0,"Снижение","По плану")))))) -> По плану | O20: =IF(C20="","",IF(LEFT(N20,6)="Пропус","",IF(N20="К тренеру, не тренироваться","",IF(N20="Лёгкий день","Л",IF(N20="Т на С с низкими %","С",C20))))) -> Л | P20: =IF(OR(N20="",N20="По плану"),0,1) -> 0 | Q20: =COUNTIFS($C$4:C19,C20,$P$4:P19,1) -> 0 | R20: =IF(B20="","",MAX(1,B20-Q20)) -> 6 | S20: =IF(C20="","",IF(R20<=3,INDEX(Настройки!$B$13:$B$16,MATCH(C20,Настройки!$A$13:$A$16,0))+Настройки!$B$7*(R20-1),IF(R20=4,INDEX(Настройки!$C$13:$C$16,MATCH(C20,Настройки!$A$13:$A$16,0)),"Новый цикл"))) -> Новый цикл | T20: =IF(OR(O20="",NOT(ISNUMBER(S20))),"",IF(N20="Т на С с низкими %",(INDEX(Настройки!$B$13:$B$16,2)+Настройки!$B$7*(MIN(R20,3)-1))-Настройки!$B$40,IF(N20="Лёгкий день",MIN(S20,(INDEX(Настройки!$B$13:$B$16,3)+Настройки!$B$7*(MIN(R20,3)-1)))-IF(C20="Л",M20,0),S20-M20))) | U20: =IF(ISNUMBER(T20),ROUND(Настройки!$B$5*T20/Настройки!$B$6,0)*Настройки!$B$6,"") | V20: =IF(O20="","",IF(NOT(ISNUMBER(S20)),S20,IF(O20="Л",INDEX(Настройки!$D$13:$G$16,3,MIN(R20,4)),INDEX(Настройки!$D$13:$G$16,MATCH(O20,Настройки!$A$13:$A$16,0),MIN(R20,4)))&IF(M20>0," (подходов не меньше 4)",""))) -> Новый цикл | Z20: =IF(AND(N(W20)>0,N(X20)>0,N(X20)+N(Y20)<=10),W20*(1+(X20+N(Y20))/30),"") | AA20: =IF(Z20="","",Z20/Настройки!$B$5-1) | AB20: =IF(AA20="",AB19,AA20) | AC20: =IF(C20="","",TRIM(IF(AND(P20=1,COUNTIFS($B$4:$B$27,B20-1,$P$4:$P$27,1)>0),"Две поправки подряд: проверить ПМ или разгрузка. ","")&IF(AA20="","",IF(AND(AA20>Настройки!$B$41,N(AB19)>Настройки!$B$41),"ПМ выше расчёта 2 раза: обновить ПМ. ",IF(AND(AA20<-Настройки!$B$41,N(AB19)<-Настройки!$B$41),"ПМ ниже расчёта 2 раза: проверить ПМ. ","")))))
B21: =IF(17<6*IF(Настройки!$B$8="С-Л-Т",3,4),INT(17/IF(Настройки!$B$8="С-Л-Т",3,4))+1,"") -> 6 | C21: =IF(B21="","",IF(Настройки!$B$8="С-Л-Т",CHOOSE(MOD(17,3)+1,"С","Л","Т"),CHOOSE(MOD(17,4)+1,"М","С","Л","Т"))) -> Т | J21: =IF(D21="","",LOOKUP(D21,Настройки!$A$21:$A$24,Настройки!$B$21:$B$24)) | K21: =IF(OR(D21="",C21=""),0,LOOKUP(D21,Настройки!$A$21:$A$24,INDEX(Настройки!$C$21:$F$24,0,MATCH(C21,Настройки!$A$13:$A$16,0)))) -> 0 | L21: =IF(E21="",0,LOOKUP(E21,Настройки!$A$29:$A$33,Настройки!$B$29:$B$33))+IF(F21="",0,LOOKUP(F21,Настройки!$A$29:$A$33,Настройки!$B$29:$B$33))+IF(G21="",0,LOOKUP(G21,Настройки!$A$29:$A$33,Настройки!$B$29:$B$33)) -> 0 | M21: =MIN(Настройки!$B$37,K21+L21) -> 0 | N21: =IF(C21="","",IF(H21="да","Пропуск: инфекция",IF(I21="да","К тренеру, не тренироваться",IF(OR(IF(D21="","Нет",LOOKUP(D21,Настройки!$A$21:$A$24,Настройки!$G$21:$G$24))="Только Л",M21>=Настройки!$B$39),"Лёгкий день",IF(AND(C21="Т",OR(IF(D21="","Нет",LOOKUP(D21,Настройки!$A$21:$A$24,Настройки!$G$21:$G$24))="Т на С",M21>=Настройки!$B$38)),"Т на С с низкими %",IF(M21>0,"Снижение","По плану")))))) -> По плану | O21: =IF(C21="","",IF(LEFT(N21,6)="Пропус","",IF(N21="К тренеру, не тренироваться","",IF(N21="Лёгкий день","Л",IF(N21="Т на С с низкими %","С",C21))))) -> Т | P21: =IF(OR(N21="",N21="По плану"),0,1) -> 0 | Q21: =COUNTIFS($C$4:C20,C21,$P$4:P20,1) -> 0 | R21: =IF(B21="","",MAX(1,B21-Q21)) -> 6 | S21: =IF(C21="","",IF(R21<=3,INDEX(Настройки!$B$13:$B$16,MATCH(C21,Настройки!$A$13:$A$16,0))+Настройки!$B$7*(R21-1),IF(R21=4,INDEX(Настройки!$C$13:$C$16,MATCH(C21,Настройки!$A$13:$A$16,0)),"Новый цикл"))) -> Новый цикл | T21: =IF(OR(O21="",NOT(ISNUMBER(S21))),"",IF(N21="Т на С с низкими %",(INDEX(Настройки!$B$13:$B$16,2)+Настройки!$B$7*(MIN(R21,3)-1))-Настройки!$B$40,IF(N21="Лёгкий день",MIN(S21,(INDEX(Настройки!$B$13:$B$16,3)+Настройки!$B$7*(MIN(R21,3)-1)))-IF(C21="Л",M21,0),S21-M21))) | U21: =IF(ISNUMBER(T21),ROUND(Настройки!$B$5*T21/Настройки!$B$6,0)*Настройки!$B$6,"") | V21: =IF(O21="","",IF(NOT(ISNUMBER(S21)),S21,IF(O21="Л",INDEX(Настройки!$D$13:$G$16,3,MIN(R21,4)),INDEX(Настройки!$D$13:$G$16,MATCH(O21,Настройки!$A$13:$A$16,0),MIN(R21,4)))&IF(M21>0," (подходов не меньше 4)",""))) -> Новый цикл | Z21: =IF(AND(N(W21)>0,N(X21)>0,N(X21)+N(Y21)<=10),W21*(1+(X21+N(Y21))/30),"") | AA21: =IF(Z21="","",Z21/Настройки!$B$5-1) | AB21: =IF(AA21="",AB20,AA21) | AC21: =IF(C21="","",TRIM(IF(AND(P21=1,COUNTIFS($B$4:$B$27,B21-1,$P$4:$P$27,1)>0),"Две поправки подряд: проверить ПМ или разгрузка. ","")&IF(AA21="","",IF(AND(AA21>Настройки!$B$41,N(AB20)>Настройки!$B$41),"ПМ выше расчёта 2 раза: обновить ПМ. ",IF(AND(AA21<-Настройки!$B$41,N(AB20)<-Настройки!$B$41),"ПМ ниже расчёта 2 раза: проверить ПМ. ","")))))
B22: =IF(18<6*IF(Настройки!$B$8="С-Л-Т",3,4),INT(18/IF(Настройки!$B$8="С-Л-Т",3,4))+1,"") | C22: =IF(B22="","",IF(Настройки!$B$8="С-Л-Т",CHOOSE(MOD(18,3)+1,"С","Л","Т"),CHOOSE(MOD(18,4)+1,"М","С","Л","Т"))) | J22: =IF(D22="","",LOOKUP(D22,Настройки!$A$21:$A$24,Настройки!$B$21:$B$24)) | K22: =IF(OR(D22="",C22=""),0,LOOKUP(D22,Настройки!$A$21:$A$24,INDEX(Настройки!$C$21:$F$24,0,MATCH(C22,Настройки!$A$13:$A$16,0)))) -> 0 | L22: =IF(E22="",0,LOOKUP(E22,Настройки!$A$29:$A$33,Настройки!$B$29:$B$33))+IF(F22="",0,LOOKUP(F22,Настройки!$A$29:$A$33,Настройки!$B$29:$B$33))+IF(G22="",0,LOOKUP(G22,Настройки!$A$29:$A$33,Настройки!$B$29:$B$33)) -> 0 | M22: =MIN(Настройки!$B$37,K22+L22) -> 0 | N22: =IF(C22="","",IF(H22="да","Пропуск: инфекция",IF(I22="да","К тренеру, не тренироваться",IF(OR(IF(D22="","Нет",LOOKUP(D22,Настройки!$A$21:$A$24,Настройки!$G$21:$G$24))="Только Л",M22>=Настройки!$B$39),"Лёгкий день",IF(AND(C22="Т",OR(IF(D22="","Нет",LOOKUP(D22,Настройки!$A$21:$A$24,Настройки!$G$21:$G$24))="Т на С",M22>=Настройки!$B$38)),"Т на С с низкими %",IF(M22>0,"Снижение","По плану")))))) | O22: =IF(C22="","",IF(LEFT(N22,6)="Пропус","",IF(N22="К тренеру, не тренироваться","",IF(N22="Лёгкий день","Л",IF(N22="Т на С с низкими %","С",C22))))) | P22: =IF(OR(N22="",N22="По плану"),0,1) -> 0 | Q22: =COUNTIFS($C$4:C21,C22,$P$4:P21,1) -> 0 | R22: =IF(B22="","",MAX(1,B22-Q22)) | S22: =IF(C22="","",IF(R22<=3,INDEX(Настройки!$B$13:$B$16,MATCH(C22,Настройки!$A$13:$A$16,0))+Настройки!$B$7*(R22-1),IF(R22=4,INDEX(Настройки!$C$13:$C$16,MATCH(C22,Настройки!$A$13:$A$16,0)),"Новый цикл"))) | T22: =IF(OR(O22="",NOT(ISNUMBER(S22))),"",IF(N22="Т на С с низкими %",(INDEX(Настройки!$B$13:$B$16,2)+Настройки!$B$7*(MIN(R22,3)-1))-Настройки!$B$40,IF(N22="Лёгкий день",MIN(S22,(INDEX(Настройки!$B$13:$B$16,3)+Настройки!$B$7*(MIN(R22,3)-1)))-IF(C22="Л",M22,0),S22-M22))) | U22: =IF(ISNUMBER(T22),ROUND(Настройки!$B$5*T22/Настройки!$B$6,0)*Настройки!$B$6,"") | V22: =IF(O22="","",IF(NOT(ISNUMBER(S22)),S22,IF(O22="Л",INDEX(Настройки!$D$13:$G$16,3,MIN(R22,4)),INDEX(Настройки!$D$13:$G$16,MATCH(O22,Настройки!$A$13:$A$16,0),MIN(R22,4)))&IF(M22>0," (подходов не меньше 4)",""))) | Z22: =IF(AND(N(W22)>0,N(X22)>0,N(X22)+N(Y22)<=10),W22*(1+(X22+N(Y22))/30),"") | AA22: =IF(Z22="","",Z22/Настройки!$B$5-1) | AB22: =IF(AA22="",AB21,AA22) | AC22: =IF(C22="","",TRIM(IF(AND(P22=1,COUNTIFS($B$4:$B$27,B22-1,$P$4:$P$27,1)>0),"Две поправки подряд: проверить ПМ или разгрузка. ","")&IF(AA22="","",IF(AND(AA22>Настройки!$B$41,N(AB21)>Настройки!$B$41),"ПМ выше расчёта 2 раза: обновить ПМ. ",IF(AND(AA22<-Настройки!$B$41,N(AB21)<-Настройки!$B$41),"ПМ ниже расчёта 2 раза: проверить ПМ. ","")))))
B23: =IF(19<6*IF(Настройки!$B$8="С-Л-Т",3,4),INT(19/IF(Настройки!$B$8="С-Л-Т",3,4))+1,"") | C23: =IF(B23="","",IF(Настройки!$B$8="С-Л-Т",CHOOSE(MOD(19,3)+1,"С","Л","Т"),CHOOSE(MOD(19,4)+1,"М","С","Л","Т"))) | J23: =IF(D23="","",LOOKUP(D23,Настройки!$A$21:$A$24,Настройки!$B$21:$B$24)) | K23: =IF(OR(D23="",C23=""),0,LOOKUP(D23,Настройки!$A$21:$A$24,INDEX(Настройки!$C$21:$F$24,0,MATCH(C23,Настройки!$A$13:$A$16,0)))) -> 0 | L23: =IF(E23="",0,LOOKUP(E23,Настройки!$A$29:$A$33,Настройки!$B$29:$B$33))+IF(F23="",0,LOOKUP(F23,Настройки!$A$29:$A$33,Настройки!$B$29:$B$33))+IF(G23="",0,LOOKUP(G23,Настройки!$A$29:$A$33,Настройки!$B$29:$B$33)) -> 0 | M23: =MIN(Настройки!$B$37,K23+L23) -> 0 | N23: =IF(C23="","",IF(H23="да","Пропуск: инфекция",IF(I23="да","К тренеру, не тренироваться",IF(OR(IF(D23="","Нет",LOOKUP(D23,Настройки!$A$21:$A$24,Настройки!$G$21:$G$24))="Только Л",M23>=Настройки!$B$39),"Лёгкий день",IF(AND(C23="Т",OR(IF(D23="","Нет",LOOKUP(D23,Настройки!$A$21:$A$24,Настройки!$G$21:$G$24))="Т на С",M23>=Настройки!$B$38)),"Т на С с низкими %",IF(M23>0,"Снижение","По плану")))))) | O23: =IF(C23="","",IF(LEFT(N23,6)="Пропус","",IF(N23="К тренеру, не тренироваться","",IF(N23="Лёгкий день","Л",IF(N23="Т на С с низкими %","С",C23))))) | P23: =IF(OR(N23="",N23="По плану"),0,1) -> 0 | Q23: =COUNTIFS($C$4:C22,C23,$P$4:P22,1) -> 0 | R23: =IF(B23="","",MAX(1,B23-Q23)) | S23: =IF(C23="","",IF(R23<=3,INDEX(Настройки!$B$13:$B$16,MATCH(C23,Настройки!$A$13:$A$16,0))+Настройки!$B$7*(R23-1),IF(R23=4,INDEX(Настройки!$C$13:$C$16,MATCH(C23,Настройки!$A$13:$A$16,0)),"Новый цикл"))) | T23: =IF(OR(O23="",NOT(ISNUMBER(S23))),"",IF(N23="Т на С с низкими %",(INDEX(Настройки!$B$13:$B$16,2)+Настройки!$B$7*(MIN(R23,3)-1))-Настройки!$B$40,IF(N23="Лёгкий день",MIN(S23,(INDEX(Настройки!$B$13:$B$16,3)+Настройки!$B$7*(MIN(R23,3)-1)))-IF(C23="Л",M23,0),S23-M23))) | U23: =IF(ISNUMBER(T23),ROUND(Настройки!$B$5*T23/Настройки!$B$6,0)*Настройки!$B$6,"") | V23: =IF(O23="","",IF(NOT(ISNUMBER(S23)),S23,IF(O23="Л",INDEX(Настройки!$D$13:$G$16,3,MIN(R23,4)),INDEX(Настройки!$D$13:$G$16,MATCH(O23,Настройки!$A$13:$A$16,0),MIN(R23,4)))&IF(M23>0," (подходов не меньше 4)",""))) | Z23: =IF(AND(N(W23)>0,N(X23)>0,N(X23)+N(Y23)<=10),W23*(1+(X23+N(Y23))/30),"") | AA23: =IF(Z23="","",Z23/Настройки!$B$5-1) | AB23: =IF(AA23="",AB22,AA23) | AC23: =IF(C23="","",TRIM(IF(AND(P23=1,COUNTIFS($B$4:$B$27,B23-1,$P$4:$P$27,1)>0),"Две поправки подряд: проверить ПМ или разгрузка. ","")&IF(AA23="","",IF(AND(AA23>Настройки!$B$41,N(AB22)>Настройки!$B$41),"ПМ выше расчёта 2 раза: обновить ПМ. ",IF(AND(AA23<-Настройки!$B$41,N(AB22)<-Настройки!$B$41),"ПМ ниже расчёта 2 раза: проверить ПМ. ","")))))
